[2020/2/28 22:44:45][ERROR][uibot38385c2483da42.task][74] 运行发生错误，流程中止
错误信息如下：
uibot38385c2483da42.task 第74行： 尝试去连接一个__lua_metatable_Python Object值 (字段 '正文')
