[2020/2/28 22:56:58][ERROR][uibot38385c2483da42.task][80] 运行发生错误，流程中止
错误信息如下：
uibot38385c2483da42.task 第80行：Python调用出错：ExecuteSQL 异常：
(1292, "Incorrect datetime value: '2月9日' for column 'date' at row 1")
