[2020/2/28 22:41:42][ERROR][uibot38385c2483da42.task][77] 运行发生错误，流程中止
错误信息如下：
uibot38385c2483da42.task 第77行： 尝试去连接一个__lua_metatable_Python Object值 (字段 'BODY')
